Workbook

Sheet Summary
A1: HVAC Monitoring System — Cost Summary
A2: Totals pull from each node sheet by phase. Edit quantities/costs (blue) on node sheets.
A4: Node | B4: V1 (core) | C4: Optional | D4: Phase 2 | E4: Future | F4: LoRa | G4: All Items
A5: Outdoor Node | B5: =SUMIFS('Outdoor Node'!$E$5:$E$49,'Outdoor Node'!$F$5:$F$49,"V1") | C5: =SUMIFS('Outdoor Node'!$E$5:$E$49,'Outdoor Node'!$F$5:$F$49,"Optional") | D5: =SUMIFS('Outdoor Node'!$E$5:$E$49,'Outdoor Node'!$F$5:$F$49,"Phase 2") | E5: =SUMIFS('Outdoor Node'!$E$5:$E$49,'Outdoor Node'!$F$5:$F$49,"Future") | F5: =SUMIFS('Outdoor Node'!$E$5:$E$49,'Outdoor Node'!$F$5:$F$49,"LoRa") | G5: =SUM(B5:F5)
A6: Indoor Node | B6: =SUMIFS('Indoor Node'!$E$5:$E$31,'Indoor Node'!$F$5:$F$31,"V1") | C6: =SUMIFS('Indoor Node'!$E$5:$E$31,'Indoor Node'!$F$5:$F$31,"Optional") | D6: =SUMIFS('Indoor Node'!$E$5:$E$31,'Indoor Node'!$F$5:$F$31,"Phase 2") | E6: =SUMIFS('Indoor Node'!$E$5:$E$31,'Indoor Node'!$F$5:$F$31,"Future") | F6: =SUMIFS('Indoor Node'!$E$5:$E$31,'Indoor Node'!$F$5:$F$31,"LoRa") | G6: =SUM(B6:F6)
A7: Display Node | B7: =SUMIFS('Display Node'!$E$5:$E$25,'Display Node'!$F$5:$F$25,"V1") | C7: =SUMIFS('Display Node'!$E$5:$E$25,'Display Node'!$F$5:$F$25,"Optional") | D7: =SUMIFS('Display Node'!$E$5:$E$25,'Display Node'!$F$5:$F$25,"Phase 2") | E7: =SUMIFS('Display Node'!$E$5:$E$25,'Display Node'!$F$5:$F$25,"Future") | F7: =SUMIFS('Display Node'!$E$5:$E$25,'Display Node'!$F$5:$F$25,"LoRa") | G7: =SUM(B7:F7)
A8: LoRa Radio | B8: =SUMIFS('LoRa Radio'!$E$5:$E$23,'LoRa Radio'!$F$5:$F$23,"V1") | C8: =SUMIFS('LoRa Radio'!$E$5:$E$23,'LoRa Radio'!$F$5:$F$23,"Optional") | D8: =SUMIFS('LoRa Radio'!$E$5:$E$23,'LoRa Radio'!$F$5:$F$23,"Phase 2") | E8: =SUMIFS('LoRa Radio'!$E$5:$E$23,'LoRa Radio'!$F$5:$F$23,"Future") | F8: =SUMIFS('LoRa Radio'!$E$5:$E$23,'LoRa Radio'!$F$5:$F$23,"LoRa") | G8: =SUM(B8:F8)
A9: Infrastructure | B9: =SUMIFS(Infrastructure!$E$5:$E$13,Infrastructure!$F$5:$F$13,"V1") | C9: =SUMIFS(Infrastructure!$E$5:$E$13,Infrastructure!$F$5:$F$13,"Optional") | D9: =SUMIFS(Infrastructure!$E$5:$E$13,Infrastructure!$F$5:$F$13,"Phase 2") | E9: =SUMIFS(Infrastructure!$E$5:$E$13,Infrastructure!$F$5:$F$13,"Future") | F9: =SUMIFS(Infrastructure!$E$5:$E$13,Infrastructure!$F$5:$F$13,"LoRa") | G9: =SUM(B9:F9)
A10: Total | B10: =SUM(B5:B9) | C10: =SUM(C5:C9) | D10: =SUM(D5:D9) | E10: =SUM(E5:E9) | F10: =SUM(F5:F9) | G10: =SUM(G5:G9)
A12: Notes
A13: • Power supply kit cost is included in each node's total (3 kits); the Power Kit sheet is not added separately.
A14: • XDB307-3 price ($73.67) is from the Amazon listing you found; other prices are estimates — verify before ordering.
A15: • Production BOM will be far lower: buy transducers direct from the manufacturer at volume and move to a custom PCB.
A16: • Phase legend: V1 = proof of concept · Optional = recommended extras · Phase 2 = electrical monitoring · Future = thermostat replacement · LoRa = 900 MHz radio (range test, node radios, gateway).
A17: • LoRa and the thermostat module follow radio/README.md and thermostat/README.md; both are designs not yet built, so treat prices as estimates.
A19: Rev B carrier boards (one board each, parts + plugs + CTs + antenna)
A20: Outdoor board rev B | B20: ='Outdoor Board Rev B'!$E$50
A21: Indoor board rev B | B21: ='Indoor Board Rev B'!$E$41
A22: Both boards | B22: =B20+B21
A23: • Not added to the Total above: most of these parts are already counted on the node and LoRa sheets.

Sheet Power Kit
A1: Power Kit — Parts List
A2: Blue = editable estimate. Prices are approximate single-unit retail (Sept 2026); links are supplier search pages.
A3: Build 3 kits — one each for outdoor, indoor and display nodes. Kit cost flows into each node sheet.
A4: Item | B4: Part / Spec | C4: Qty | D4: Est. Unit Cost ($) | E4: Line Total ($) | F4: Phase | G4: Supplier | H4: Link | I4: Notes
A5: Power supply kit parts
A6: Inline fuse holder | B6: 5x20mm or ATO, 18 AWG leads | C6: 1 | D6: 3 | E6: =C6*D6 | F6: V1 | G6: DigiKey | H6: Search | I6: Install on R
A7: Fuse | B7: 0.5 A fast-blow | C7: 1 | D7: 1 | E7: =C7*D7 | F7: V1 | G7: DigiKey | H7: Search
A8: TVS diode | B8: SMBJ48CA bidirectional | C8: 1 | D8: 0.5 | E8: =C8*D8 | F8: V1 | G8: DigiKey | H8: Search | I8: Across 24 VAC input; clamps contactor coil spikes
A9: Rectifier diode | B9: 1N4007 | C9: 1 | D9: 0.1 | E9: =C9*D9 | F9: V1 | G9: DigiKey | H9: Search | I9: Half-wave: keeps C as DC ground
A10: Bulk capacitor | B10: 470 µF 63 V electrolytic | C10: 1 | D10: 0.6 | E10: =C10*D10 | F10: V1 | G10: DigiKey | H10: Search
A11: Bypass capacitor | B11: 0.1 µF 100 V ceramic | C11: 1 | D11: 0.1 | E11: =C11*D11 | F11: V1 | G11: DigiKey | H11: Search
A12: Buck converter module | B12: LM2596HV (60 V input), set to 5.0 V | C12: 1 | D12: 4 | E12: =C12*D12 | F12: V1 | G12: Amazon | H12: Search | I12: Must be HV version; 24 VAC rectifies to ~40 V peak
A13: Terminal block | B13: 2-pos pluggable 5.08 mm | C13: 1 | D13: 1 | E13: =C13*D13 | F13: V1 | G13: DigiKey | H13: Search | I13: R, C input
D15: Total | E15: =SUM(E5:E13)

Sheet Outdoor Node
A1: Outdoor Node — Parts List
A2: Blue = editable estimate. Prices are approximate single-unit retail (Sept 2026); links are supplier search pages.
A4: Item | B4: Part / Spec | C4: Qty | D4: Est. Unit Cost ($) | E4: Line Total ($) | F4: Phase | G4: Supplier | H4: Link | I4: Notes
A5: Controller & interface
A6: ESP32 dev board | B6: ESP32-WROOM-32U (external antenna) | C6: 1 | D6: 10 | E6: =C6*D6 | F6: V1 | G6: Amazon | H6: Search | I6: Metal cabinet blocks WiFi
A7: Antenna + pigtail | B7: 2.4 GHz antenna, u.FL to RP-SMA bulkhead | C7: 1 | D7: 8 | E7: =C7*D7 | F7: V1 | G7: Amazon | H7: Search | I7: Mount antenna outside cabinet
A8: Power supply kit | B8: See 'Power Kit' sheet | C8: 1 | D8: ='Power Kit'!$E$15 | E8: =C8*D8 | F8: V1 | G8: Built in-house | I8: Cost links to Power Kit sheet
A9: ADC module | B9: ADS1115 16-bit, 4-ch | C9: 2 | D9: 6 | E9: =C9*D9 | F9: V1 | G9: Amazon | H9: Search | I9: Addresses 0x48 / 0x49; run at 3.3 V
A10: AC-input optocoupler | B10: H11AA1 | C10: 3 | D10: 0.8 | E10: =C10*D10 | F10: V1 | G10: DigiKey | H10: Search | I10: Y, O/B, spare
A11: Opto series resistor | B11: 4.7k ½ W | C11: 3 | D11: 0.1 | E11: =C11*D11 | F11: V1 | G11: DigiKey | H11: Search | I11: One per opto input
A12: Opto pull-up resistor | B12: 10k ¼ W | C12: 3 | D12: 0.05 | E12: =C12*D12 | F12: V1 | G12: DigiKey | H12: Search | I12: One per opto output
A13: Refrigerant sensors
A14: Pressure transducer (high/vapor) | B14: XDB307-3, 0.5–4.5 V, 5–12 V, 0–50 bar, 7/16-20 UNF | C14: 2 | D14: 73.67 | E14: =C14*D14 | F14: V1 | G14: Amazon | H14: Search | I14: Liquid line + vapor line port. Price from Amazon listing (LDGSUPH). Confirm depressor with seller
A15: Pressure transducer (true suction) | B15: XDB307-3, 0.5–4.5 V, 0–35 bar | C15: 1 | D15: 73.67 | E15: =C15*D15 | F15: V1 | G15: Amazon | H15: Search | I15: Never sees discharge pressure
A16: Pipe thermistor | B16: 10k NTC strap-on | C16: 2 | D16: 12 | E16: =C16*D16 | F16: V1 | G16: Amazon | H16: Search | I16: Suction line + liquid line
A17: Pipe thermistor (true suction) | B17: 10k NTC strap-on | C17: 1 | D17: 12 | E17: =C17*D17 | F17: Optional | G17: Amazon | H17: Search | I17: Heating-mode superheat
A18: Discharge line thermistor | B18: High-temp 10k NTC, 150 °C+ | C18: 1 | D18: 15 | E18: =C18*D18 | F18: Optional | G18: Amazon | H18: Search | I18: Compressor health indicator
A19: Signal conditioning
A20: Divider resistor (top) | B20: 10k 1% metal film | C20: 3 | D20: 0.05 | E20: =C20*D20 | F20: V1 | G20: DigiKey | H20: Search | I20: Sensor dividers: 4.5 V -> 3.0 V
A21: Divider resistor (bottom) | B21: 20k 1% metal film | C21: 3 | D21: 0.05 | E21: =C21*D21 | F21: V1 | G21: DigiKey | H21: Search | I21: R2, R4, R6. 10k also works: set P_DIV_BOTTOM_K 10.0 in config.h
A22: Rail monitor divider | B22: 10k + 15k 1% (pair) | C22: 1 | D22: 0.1 | E22: =C22*D22 | F22: V1 | G22: DigiKey | H22: Search | I22: R7 (10k) / R8 (15k): measures the 5 V rail for ratiometric correction. R8 may be 10k (RAIL_DIV_BOTTOM_K 10.0); 15k is the most it can be
A23: Thermistor reference resistor | B23: 10k 0.1% | C23: 4 | D23: 0.5 | E23: =C23*D23 | F23: V1 | G23: DigiKey | H23: Search | I23: 2 used in V1, 2 for optional thermistors
A24: ADC filter capacitor | B24: 0.1 µF ceramic | C24: 7 | D24: 0.1 | E24: =C24*D24 | F24: V1 | G24: DigiKey | H24: Search | I24: One per ADC input
A25: Outdoor air
A26: Temp/humidity sensor | B26: SHT45 with PTFE membrane | C26: 1 | D26: 15 | E26: =C26*D26 | F26: V1 | G26: Amazon | H26: Search | I26: I²C 0x44
A27: Radiation shield | B27: Solar radiation shield | C27: 1 | D27: 25 | E27: =C27*D27 | F27: V1 | G27: Amazon | H27: Search | I27: Keeps sun off the SHT45
A28: Refrigerant hardware
A29: Access valve | B29: Braze-on 1/4" SAE access valve, sized to line | C29: 1 | D29: 6 | E29: =C29*D29 | F29: V1 | G29: HVAC supply house | H29: Search | I29: True suction port; requires brazing + EPA 608
A30: Flare gaskets | B30: 1/4" flare copper gaskets / seals | C30: 1 | D30: 8 | E30: =C30*D30 | F30: V1 | G30: Amazon | H30: Search | I30: Pack
A31: Flare hose | B31: Short 1/4" flare hose, F x M | C31: 3 | D31: 12 | E31: =C31*D31 | F31: Optional | G31: Amazon | H31: Search | I31: Isolates sensors from vibration
A32: Schrader cores & caps | B32: Spare kit | C32: 1 | D32: 10 | E32: =C32*D32 | F32: V1 | G32: Amazon | H32: Search
A33: Enclosure & wiring
A34: Enclosure | B34: IP65 ABS, ~200×150×75 mm | C34: 1 | D34: 25 | E34: =C34*D34 | F34: V1 | G34: Amazon | H34: Search | I34: Mount outside compressor compartment
A35: Cable glands | B35: PG7 / PG9 assortment | C35: 1 | D35: 10 | E35: =C35*D35 | F35: V1 | G35: Amazon | H35: Search
A36: Prototype board | B36: Perfboard / proto PCB | C36: 1 | D36: 8 | E36: =C36*D36 | F36: V1 | G36: Amazon | H36: Search
A37: Terminal blocks | B37: Pluggable 5.08 mm assortment | C37: 1 | D37: 12 | E37: =C37*D37 | F37: V1 | G37: Amazon | H37: Search
A38: Sensor cable | B38: 22 AWG shielded 3-cond, 50 ft | C38: 1 | D38: 25 | E38: =C38*D38 | F38: V1 | G38: Amazon | H38: Search
A39: Thermostat wire | B39: 18/5, 50 ft | C39: 1 | D39: 30 | E39: =C39*D39 | F39: V1 | G39: Amazon | H39: Search
A40: Insulation tape | B40: Foam pipe insulation tape | C40: 1 | D40: 10 | E40: =C40*D40 | F40: V1 | G40: Amazon | H40: Search | I40: Over thermistors
A41: Zip ties | B41: UV-rated / stainless | C41: 1 | D41: 8 | E41: =C41*D41 | F41: V1 | G41: Amazon | H41: Search
...

Sheet Indoor Node
A1: Indoor Node — Parts List
A2: Blue = editable estimate. Prices are approximate single-unit retail (Sept 2026); links are supplier search pages.
A4: Item | B4: Part / Spec | C4: Qty | D4: Est. Unit Cost ($) | E4: Line Total ($) | F4: Phase | G4: Supplier | H4: Link | I4: Notes
A5: Controller & interface
A6: ESP32 dev board | B6: ESP32-WROOM-32U (external antenna) | C6: 1 | D6: 10 | E6: =C6*D6 | F6: V1 | G6: Amazon | H6: Search | I6: Furnace cabinet blocks WiFi
A7: Antenna + pigtail | B7: 2.4 GHz antenna, u.FL to RP-SMA | C7: 1 | D7: 8 | E7: =C7*D7 | F7: V1 | G7: Amazon | H7: Search
A8: Power supply kit | B8: See 'Power Kit' sheet | C8: 1 | D8: ='Power Kit'!$E$15 | E8: =C8*D8 | F8: V1 | G8: Built in-house | I8: Cost links to Power Kit sheet
A9: I²C multiplexer | B9: TCA9548A | C9: 1 | D9: 6 | E9: =C9*D9 | F9: V1 | G9: Amazon | H9: Search | I9: SDP810s share one address
A10: AC-input optocoupler | B10: H11AA1 | C10: 4 | D10: 0.8 | E10: =C10*D10 | F10: V1 | G10: DigiKey | H10: Search | I10: Y, W, G, O/B
A11: Opto series resistor | B11: 4.7k ½ W | C11: 4 | D11: 0.1 | E11: =C11*D11 | F11: V1 | G11: DigiKey | H11: Search | I11: One per opto input
A12: Opto pull-up resistor | B12: 10k ¼ W | C12: 4 | D12: 0.05 | E12: =C12*D12 | F12: V1 | G12: DigiKey | H12: Search | I12: One per opto output
A13: I²C extender | B13: PCA9615 differential I²C | C13: 2 | D13: 12 | E13: =C13*D13 | F13: Optional | G13: Amazon | H13: Search | I13: For runs over ~1 m
A14: Air sensors
A15: Duct temp/humidity probe | B15: SHT45 probe with PTFE membrane | C15: 2 | D15: 25 | E15: =C15*D15 | F15: V1 | G15: Amazon | H15: Search | I15: Supply + return
A16: Differential pressure sensor | B16: Sensirion SDP810-500Pa | C16: 3 | D16: 45 | E16: =C16*D16 | F16: V1 | G16: DigiKey | H16: Search | I16: Return, furnace-to-coil, supply
A17: Static pressure tip | B17: Dwyer A-301 style | C17: 3 | D17: 15 | E17: =C17*D17 | F17: V1 | G17: HVAC supply house | H17: Search
A18: Grommets | B18: Rubber grommets for tips | C18: 1 | D18: 5 | E18: =C18*D18 | F18: V1 | G18: Amazon | H18: Search
A19: Silicone tubing | B19: 3/16" ID, ~10 ft | C19: 1 | D19: 10 | E19: =C19*D19 | F19: V1 | G19: Amazon | H19: Search
A20: Filter pressure sensor | B20: SDP810-500Pa | C20: 1 | D20: 45 | E20: =C20*D20 | F20: Optional | G20: DigiKey | H20: Search | I20: Filter pressure drop
A21: Filter static tip | B21: Dwyer A-301 style | C21: 1 | D21: 15 | E21: =C21*D21 | F21: Optional | G21: HVAC supply house | H21: Search
A22: Enclosure & wiring
A23: Enclosure | B23: ABS project box | C23: 1 | D23: 15 | E23: =C23*D23 | F23: V1 | G23: Amazon | H23: Search
A24: I²C cable | B24: 22 AWG shielded 4-cond, 50 ft | C24: 1 | D24: 25 | E24: =C24*D24 | F24: V1 | G24: Amazon | H24: Search
A25: Thermostat wire | B25: 18/5, 50 ft | C25: 1 | D25: 30 | E25: =C25*D25 | F25: V1 | G25: Amazon | H25: Search
A26: Glands, terminals, perfboard | B26: Assortment | C26: 1 | D26: 20 | E26: =C26*D26 | F26: V1 | G26: Amazon | H26: Search
A27: Phase 2 electrical
A28: Energy monitor board | B28: ATM90E32-based | C28: 1 | D28: 80 | E28: =C28*D28 | F28: Phase 2 | G28: CircuitSetup | H28: Search
A29: Current transformer | B29: Split-core CT | C29: 2 | D29: 12 | E29: =C29*D29 | F29: Phase 2 | G29: Amazon | H29: Search | I29: Blower + inducer (inducer optional)
A30: Isolated amplifier | B30: AMC1311 or similar | C30: 1 | D30: 15 | E30: =C30*D30 | F30: Phase 2 | G30: DigiKey | H30: Search | I30: PSC blower capacitor voltage
A31: Voltage reference transformer | B31: Matched to 120 or 240 V equipment | C31: 1 | D31: 12 | E31: =C31*D31 | F31: Phase 2 | G31: Amazon | H31: Search
D33: Total | E33: =SUM(E5:E31)

Sheet Display Node
A1: Display Node — Parts List
A2: Blue = editable estimate. Prices are approximate single-unit retail (Sept 2026); links are supplier search pages.
A4: Item | B4: Part / Spec | C4: Qty | D4: Est. Unit Cost ($) | E4: Line Total ($) | F4: Phase | G4: Supplier | H4: Link | I4: Notes
A5: Display & power
A6: Touch display board | B6: Waveshare ESP32-S3 4.3" Touch LCD | C6: 1 | D6: 40 | E6: =C6*D6 | F6: V1 | G6: Amazon | H6: Search | I6: 800 × 480 touchscreen; also the system hub and (with LoRa) the gateway
A7: Power supply kit | B7: See 'Power Kit' sheet | C7: 1 | D7: ='Power Kit'!$E$15 | E7: =C7*D7 | F7: V1 | G7: Built in-house | I7: Needs C wire at thermostat
A8: C-wire adapter | B8: Venstar Add-a-Wire | C8: 1 | D8: 30 | E8: =C8*D8 | F8: Optional | G8: Amazon | H8: Search | I8: Only if no C wire
A9: Wall mount | B9: Enclosure or 3D-printed bezel | C9: 1 | D9: 15 | E9: =C9*D9 | F9: V1 | G9: 3D print / Amazon
A10: Room temp/humidity | B10: SHT45 | C10: 1 | D10: 15 | E10: =C10*D10 | F10: Optional | G10: Amazon | H10: Search | I10: For the display-only version. The thermostat version uses the one in its section below
A11: Alarm buzzer | B11: Piezo buzzer | C11: 1 | D11: 1 | E11: =C11*D11 | F11: Optional | G11: Amazon | H11: Search
A12: Thermostat-replacement version (see thermostat/README.md)
A13: Output switches | B13: PhotoMOS solid-state relay, 60 V AC/DC, 2.5 A (Panasonic AQV252G) | C13: 6 | D13: 5 | E13: =C13*D13 | F13: Future | G13: DigiKey | H13: Search | I13: Y, Y2, W, W2, G, O/B. Open on reset/power loss; silent, no contact wear
A14: Output surge clamp | B14: TVS diode SMBJ36CA bidirectional | C14: 6 | D14: 0.5 | E14: =C14*D14 | F14: Future | G14: DigiKey | H14: Search | I14: Across each output: clamps contactor/valve coil kick below the 60 V switch rating
A15: SSR LED resistor | B15: 330 Ω ¼ W | C15: 6 | D15: 0.05 | E15: =C15*D15 | F15: Future | G15: DigiKey | H15: Search | I15: ~5 mA from 3.3 V into each PhotoMOS LED
A16: I/O expander | B16: MCP23017 I²C 16-bit GPIO expander | C16: 1 | D16: 2 | E16: =C16*D16 | F16: Future | G16: DigiKey | H16: Search | I16: 6 outputs + watchdog line + 5 state-sense inputs over I²C (the 4.3" board's GPIOs go to the LCD). Resets to all-off
A17: Hardware watchdog | B17: TI TPS3823-33 supervisor with watchdog | C17: 1 | D17: 1.5 | E17: =C17*D17 | F17: Future | G17: DigiKey | H17: Search | I17: Its RESET drives the ESP32 EN and the MCP23017 RESET: if the firmware stops, every output turns off
A18: State-sense optos | B18: H11AA1 | C18: 5 | D18: 0.8 | E18: =C18*D18 | F18: Future | G18: DigiKey | H18: Search | I18: Read back what the equipment actually gets (Y, Y2, W, G, O/B)
A19: Opto series resistor | B19: 4.7k ½ W | C19: 5 | D19: 0.1 | E19: =C19*D19 | F19: Future | G19: DigiKey | H19: Search | I19: One per state-sense input
A20: Opto pull-up resistor | B20: 10k ¼ W | C20: 5 | D20: 0.05 | E20: =C20*D20 | F20: Future | G20: DigiKey | H20: Search | I20: One per opto output
A21: Room temp/humidity (control) | B21: SHT45 on a thermally isolated tab / short flex cable | C21: 1 | D21: 15 | E21: =C21*D21 | F21: Future | G21: Amazon | H21: Search | I21: Controls the house: keep it away from the display and regulator heat
A22: Wiring terminal block | B22: 8-pos pluggable 5.08 mm (R, C, Y, Y2, W, W2, G, O/B) | C22: 1 | D22: 3 | E22: =C22*D22 | F22: Future | G22: DigiKey | H22: Search | I22: Labelled like a standard thermostat sub-base
A23: Output carrier PCB | B23: Small 2-layer board for the switches, optos and terminals (JLCPCB, 5 pcs) | C23: 1 | D23: 20 | E23: =C23*D23 | F23: Future | G23: JLCPCB | H23: Search | I23: Mounts behind the display board; I²C + 5 V from the power kit
A24: Connectors & jumpers | B24: JST-SH / Dupont jumper set | C24: 1 | D24: 6 | E24: =C24*D24 | F24: Future | G24: Amazon | H24: Search | I24: Display board to output carrier
A25: Wall back plate | B25: 3D-printed back plate with wire opening + screws/anchors | C25: 1 | D25: 8 | E25: =C25*D25 | F25: Future | G25: 3D print / Amazon | I25: Replaces the old thermostat's sub-base
D27: Total | E27: =SUM(E5:E25)

Sheet LoRa Radio
A1: LoRa Radio (900 MHz) — Parts List
A2: Blue = editable estimate. Prices are approximate single-unit retail (Oct 2026); links are supplier search pages.
A3: From radio/README.md (branch radio/lora-design): one fixed 500 kHz channel in 902–928 MHz, SX1262 radios, gateway built into the thermostat or a plug-in unit.
A4: Item | B4: Part / Spec | C4: Qty | D4: Est. Unit Cost ($) | E4: Line Total ($) | F4: Phase | G4: Supplier | H4: Link | I4: Notes
A5: Range test (do first: decides LoRa vs WiFi)
A6: LoRa dev board | B6: Heltec WiFi LoRa 32 V3, 915 MHz version (ESP32-S3 + SX1262, OLED) | C6: 2 | D6: 22 | E6: =C6*D6 | F6: LoRa | G6: Heltec | H6: Search | I6: Sender + receiver for the range test (radio/rangetest firmware)
A7: Antenna | B7: 915 MHz 3 dBi, SMA, with u.FL-to-SMA pigtail | C7: 2 | D7: 8 | E7: =C7*D7 | F7: LoRa | G7: Amazon | H7: Search | I7: Must be 915 MHz, not 868
A8: USB power bank | B8: Any, USB-C | C8: 1 | D8: 20 | E8: =C8*D8 | F8: Optional | G8: Amazon | H8: Search | I8: Powers the sender on the walk-around. Skip if owned
A9: Node radios (outdoor + indoor)
A10: LoRa radio module | B10: Seeed Wio-SX1262 (SX1262, FCC modular approval Z4T-WIO-SX1262) | C10: 2 | D10: 9 | E10: =C10*D10 | F10: LoRa | G10: Seeed | H10: Search | I10: On SPI of each node's ESP32; solder to carrier rev B or a breakout
A11: Module breakout | B11: Castellated-module breakout / adapter board | C11: 0 | D11: 3 | E11: =C11*D11 | F11: LoRa | G11: Amazon | H11: Search | I11: Not needed: rev B boards have the Wio-SX1262 footprint (qty 0 = not in the totals)
A12: Antenna (outside the cabinet) | B12: 915 MHz 3 dBi, outdoor-rated, SMA bulkhead | C12: 2 | D12: 12 | E12: =C12*D12 | F12: LoRa | G12: Amazon | H12: Search | I12: Sheet-metal cabinets block the signal: mount outside, as with the WiFi antenna
A13: RF pigtail | B13: u.FL (IPEX) to SMA bulkhead, 15 cm | C13: 2 | D13: 4 | E13: =C13*D13 | F13: LoRa | G13: Amazon | H13: Search
A14: Coax extension | B14: RG316 SMA male–female, 1 m | C14: 2 | D14: 6 | E14: =C14*D14 | F14: Optional | G14: Amazon | H14: Search | I14: Only if the antenna can't sit at the enclosure
A15: Gateway
A16: Thermostat built-in gateway | B16: Seeed Wio-SX1262 on the display board's SPI | C16: 1 | D16: 9 | E16: =C16*D16 | F16: LoRa | G16: Seeed | H16: Search | I16: Confirm free SPI + 3 GPIO on the Waveshare 4.3" board; otherwise use the plug-in gateway
A17: Gateway antenna | B17: 915 MHz 2–3 dBi, small SMA or internal flex | C17: 1 | D17: 6 | E17: =C17*D17 | F17: LoRa | G17: Amazon | H17: Search | I17: Inside the thermostat housing
A18: Plug-in gateway (no thermostat) | B18: Heltec WiFi LoRa 32 V3, 915 MHz | C18: 1 | D18: 22 | E18: =C18*D18 | F18: Optional | G18: Heltec | H18: Search | I18: For homes that keep their own thermostat; the range-test receiver can become this
A19: Gateway power | B19: USB-C 5 V 1 A wall adapter | C19: 1 | D19: 8 | E19: =C19*D19 | F19: Optional | G19: Amazon | H19: Search
A20: Gateway enclosure | B20: Small ABS box or 3D-printed case | C20: 1 | D20: 8 | E20: =C20*D20 | F20: Optional | G20: Amazon | H20: Search
A21: Production modules (for reference; qty 0 = not in the totals)
A22: All-in-one node module | B22: Heltec HT-CT62 (ESP32-C3 + SX1262), FCC 2A2GJ-HT-CT62 | C22: 0 | D22: 7 | E22: =C22*D22 | F22: Future | G22: Heltec | H22: Search | I22: Replaces ESP32 + radio on a custom board
A23: MCU + radio module | B23: RAKwireless RAK3172 (STM32WL), FCC 2AF6B-RAK3172 | C23: 0 | D23: 9 | E23: =C23*D23 | F23: Future | G23: RAKwireless | H23: Search | I23: Alternative
D25: Total | E25: =SUM(E5:E23)
A27: • Before buying production modules, confirm each module's FCC grant covers 500 kHz DTS operation at the power used, and its approved antennas.
A28: • The WiFi antennas on the outdoor/indoor sheets stay: nodes keep WiFi-direct mode when there is no gateway.

Sheet Infrastructure
A1: Infrastructure — Parts List
A2: Blue = editable estimate. Prices are approximate single-unit retail (Sept 2026); links are supplier search pages.
A4: Item | B4: Part / Spec | C4: Qty | D4: Est. Unit Cost ($) | E4: Line Total ($) | F4: Phase | G4: Supplier | H4: Link | I4: Notes
A5: Prototype infrastructure
A6: Home Assistant server | B6: Home Assistant Green (or Raspberry Pi 5 4 GB) | C6: 1 | D6: 129 | E6: =C6*D6 | F6: V1 | G6: Amazon | H6: Search | I6: Runs HA + ESPHome
A7: Bench transformer | B7: 24 VAC 40 VA | C7: 1 | D7: 15 | E7: =C7*D7 | F7: V1 | G7: Amazon | H7: Search
A8: Breadboard kit | B8: Breadboards + jumper wires | C8: 1 | D8: 20 | E8: =C8*D8 | F8: V1 | G8: Amazon | H8: Search
A9: USB cables | B9: USB-C / micro-USB assortment | C9: 1 | D9: 10 | E9: =C9*D9 | F9: V1 | G9: Amazon | H9: Search
A10: Heat shrink | B10: Assortment | C10: 1 | D10: 10 | E10: =C10*D10 | F10: V1 | G10: Amazon | H10: Search
A11: Multimeter | B11: True RMS | C11: 1 | D11: 40 | E11: =C11*D11 | F11: Optional | G11: Amazon | H11: Search | I11: Skip if owned
A12: Soldering station | B12: Temp-controlled | C12: 1 | D12: 60 | E12: =C12*D12 | F12: Optional | G12: Amazon | H12: Search | I12: Skip if owned
A13: Reference gauge | B13: Digital manifold / probes | C13: 1 | D13: 0 | E13: =C13*D13 | F13: V1 | G13: Owned | I13: Existing Fieldpiece probes for calibration
D15: Total | E15: =SUM(E5:E13)

Sheet Outdoor Board Rev B
A1: Outdoor Carrier Rev B — Board Parts
A2: Blue = editable estimate. Prices are approximate single-unit retail (Oct 2026); links are supplier search pages. Refs match the board silkscreen and fab/*-BOM.csv.
A3: Outdoor carrier rev B: 100 x 100 mm. Hand-built with plug-in ESP32, ADS1115 and LM2596 modules.
A4: Item | B4: Part / Spec | C4: Qty | D4: Est. Unit Cost ($) | E4: Line Total ($) | F4: Phase | G4: Supplier | H4: Link | I4: Notes
A5: Controller & power
A6: Bare PCB | B6: 100 x 100 mm, 2-layer 1.6 mm, JLCPCB (5 pcs per order) | C6: 1 | D6: 3 | E6: =C6*D6 | F6: V1 | G6: JLCPCB | H6: Search | I6: About $15 for 5 boards with shipping; inside JLCPCB's cheapest 100 x 100 mm size. Gerbers: fab/*-JLCPCB-gerbers.zip
A7: ESP32 dev board (U1) | B7: ESP32-WROOM-32 DevKit, 30-pin, 25.4 mm row spacing | C7: 1 | D7: 7 | E7: =C7*D7 | F7: V1 | G7: Amazon | H7: Search | I7: Check the 25.4 mm (1.0") row spacing before buying
A8: Female headers for U1 | B8: 15-pin 2.54 mm female header | C8: 2 | D8: 0.5 | E8: =C8*D8 | F8: V1 | G8: Amazon | H8: Search | I8: Lets the ESP32 plug in and out
A9: Bulk capacitor (C1) | B9: 470 µF 63 V electrolytic, radial 10 mm, 5 mm pitch | C9: 1 | D9: 0.6 | E9: =C9*D9 | F9: V1 | G9: DigiKey | H9: Search
A10: TVS diode (D1) | B10: SMBJ48CA bidirectional, SMB | C10: 1 | D10: 0.5 | E10: =C10*D10 | F10: V1 | G10: DigiKey | H10: Search | I10: Across the 24 VAC input
A11: Rectifier diode (D2) | B11: 1N4007, DO-41 | C11: 1 | D11: 0.1 | E11: =C11*D11 | F11: V1 | G11: DigiKey | H11: Search | I11: Half-wave: keeps C as DC ground
A12: Fuse clips (F1) | B12: 5x20 mm PCB fuse clip (Littelfuse 111 style) | C12: 2 | D12: 0.3 | E12: =C12*D12 | F12: V1 | G12: DigiKey | H12: Search | I12: Two clips per fuse
A13: Fuse (F1) | B13: 0.5 A fast-blow, 5x20 mm | C13: 1 | D13: 0.5 | E13: =C13*D13 | F13: V1 | G13: DigiKey | H13: Search
A14: Buck module (U2) | B14: LM2596HV module (60 V input), set to 5.00 V before fitting | C14: 1 | D14: 4 | E14: =C14*D14 | F14: V1 | G14: Amazon | H14: Search | I14: Must be the HV version: 24 VAC rectifies to ~40 V peak
A15: Bypass capacitors (C2-C10, C17) | B15: 0.1 µF ceramic disc, 2.5 mm pitch | C15: 10 | D15: 0.1 | E15: =C15*D15 | F15: V1 | G15: DigiKey | H15: Search | I15: C17 is the radio decoupling cap listed below; counted here
A16: SETUP button (SW1) | B16: 6 mm through-hole tactile switch | C16: 1 | D16: 0.2 | E16: =C16*D16 | F16: V1 | G16: DigiKey | H16: Search | I16: GPIO14; reserved for Bluetooth setup, no firmware yet
A17: Sensor inputs
A18: ADC module (U3, U4) | B18: ADS1115 breakout, 10-pin (0x48 and 0x49) | C18: 2 | D18: 6 | E18: =C18*D18 | F18: V1 | G18: Amazon | H18: Search | I18: Plug-in; 0x48 pressures + rail, 0x49 thermistors
A19: Female headers for U3, U4 | B19: 10-pin 2.54 mm female header | C19: 2 | D19: 0.4 | E19: =C19*D19 | F19: V1 | G19: Amazon | H19: Search
A20: Divider resistors (R1-R8) | B20: 10k 1% metal film, ¼ W | C20: 8 | D20: 0.05 | E20: =C20*D20 | F20: V1 | G20: DigiKey | H20: Search | I20: Rev B uses 10k for both halves (firmware default)
A21: Thermistor references (R9, R10, R15, R16) | B21: 10k 0.1% metal film, ¼ W | C21: 4 | D21: 0.5 | E21: =C21*D21 | F21: V1 | G21: DigiKey | H21: Search | I21: R15 (true suction) and R16 (discharge) only needed when those thermistors are fitted
A22: Mode-input optos (U5, U6) | B22: H11AA1, DIP-6 | C22: 2 | D22: 0.8 | E22: =C22*D22 | F22: V1 | G22: DigiKey | H22: Search | I22: Y and O/B
A23: DIP-6 sockets for U5, U6 | B23: 6-pin DIP socket, 7.62 mm | C23: 2 | D23: 0.2 | E23: =C23*D23 | F23: V1 | G23: DigiKey | H23: Search
A24: Opto series resistors (R11, R13) | B24: 4.7k ½ W | C24: 2 | D24: 0.1 | E24: =C24*D24 | F24: V1 | G24: DigiKey | H24: Search
A25: Opto pull-ups (R12, R14) | B25: 10k ¼ W | C25: 2 | D25: 0.05 | E25: =C25*D25 | F25: V1 | G25: DigiKey | H25: Search
A26: Current sensors (electrical module version 1)
A27: CT jacks (J11-J13) | B27: CUI SJ1-3523N 3.5 mm stereo jack | C27: 3 | D27: 1.2 | E27: =C27*D27 | F27: V1 | G27: DigiKey | H27: Search | I27: Sits in an edge notch; check fit on a real part
A28: CT bias divider (R17, R18) | B28: 10k + 6.8k 1%, 0805 | C28: 2 | D28: 0.05 | E28: =C28*D28 | F28: V1 | G28: DigiKey | H28: Search | I28: CT_BIAS ≈ 1.34 V
A29: CT bias cap (C11) | B29: 10 µF 16 V electrolytic, radial 5 mm | C29: 1 | D29: 0.15 | E29: =C29*D29 | F29: V1 | G29: DigiKey | H29: Search
A30: CT1 burden resistor (R19) | B30: 18 Ω 1%, 0805 | C30: 1 | D30: 0.05 | E30: =C30*D30 | F30: V1 | G30: DigiKey | H30: Search | I30: Only CT1 (SCT-013-000) needs a burden; R21, R23 left empty
A31: CT filter resistors (R20, R22, R24) | B31: 1k, 0805 | C31: 3 | D31: 0.05 | E31: =C31*D31 | F31: V1 | G31: DigiKey | H31: Search
A32: CT filter caps (C12-C14) | B32: 10 nF, 0805 | C32: 3 | D32: 0.05 | E32: =C32*D32 | F32: V1 | G32: DigiKey | H32: Search
A33: CT1 compressor | B33: SCT-013-000 (100 A, current output) | C33: 1 | D33: 8 | E33: =C33*D33 | F33: V1 | G33: Amazon | H33: Search | I33: Clamps the compressor common
A34: CT2 fan | B34: SCT-013-005 (5 A / 1 V) | C34: 1 | D34: 8 | E34: =C34*D34 | F34: V1 | G34: Amazon | H34: Search | I34: Condenser fan
A35: CT3 HERM | B35: SCT-013-010 (10 A / 1 V) | C35: 1 | D35: 8 | E35: =C35*D35 | F35: V1 | G35: Amazon | H35: Search | I35: Run-capacitor HERM lead
A36: Connectors (board side + mating plug)
A37: Pluggable terminal (J1) | B37: Phoenix MC 1,5/2-G-5.08 header + MC 1,5/2-ST-5.08 plug | C37: 1 | D37: 2 | E37: =C37*D37 | F37: V1 | G37: DigiKey | H37: Search | I37: 24 VAC in (R, C)
A38: Pluggable terminal (J2) | B38: Phoenix MC 1,5/2-G-5.08 header + MC 1,5/2-ST-5.08 plug | C38: 1 | D38: 2 | E38: =C38*D38 | F38: V1 | G38: DigiKey | H38: Search | I38: Y, O/B call inputs
A39: Pluggable terminal (J8) | B39: Phoenix MC 1,5/4-G-5.08 header + MC 1,5/4-ST-5.08 plug | C39: 1 | D39: 3 | E39: =C39*D39 | F39: V1 | G39: DigiKey | H39: Search | I39: Outdoor air sensor (SHT30 / FS400)
A40: JST-XH 3-pin jack (J3-J5) | B40: B3B-XH-A vertical + XHP-3 housing + SXH crimps | C40: 3 | D40: 0.3 | E40: =C40*D40 | F40: V1 | G40: DigiKey | H40: Search | I40: Pressure transducers: liquid, vapor, true suction (J5 spare until fitted)
...

Sheet Indoor Board Rev B
A1: Indoor Carrier Rev B — Board Parts
A2: Blue = editable estimate. Prices are approximate single-unit retail (Oct 2026); links are supplier search pages. Refs match the board silkscreen and fab/*-BOM.csv.
A3: Indoor carrier rev B: 100 x 88 mm. Hand-built with plug-in ESP32 and LM2596 modules; TCA9548A soldered on.
A4: Item | B4: Part / Spec | C4: Qty | D4: Est. Unit Cost ($) | E4: Line Total ($) | F4: Phase | G4: Supplier | H4: Link | I4: Notes
A5: Controller & power
A6: Bare PCB | B6: 100 x 88 mm, 2-layer 1.6 mm, JLCPCB (5 pcs per order) | C6: 1 | D6: 3 | E6: =C6*D6 | F6: V1 | G6: JLCPCB | H6: Search | I6: About $15 for 5 boards with shipping; inside JLCPCB's cheapest 100 x 100 mm size. Gerbers: fab/*-JLCPCB-gerbers.zip
A7: ESP32 dev board (U1) | B7: ESP32-WROOM-32 DevKit, 30-pin, 25.4 mm row spacing | C7: 1 | D7: 7 | E7: =C7*D7 | F7: V1 | G7: Amazon | H7: Search | I7: Check the 25.4 mm (1.0") row spacing before buying
A8: Female headers for U1 | B8: 15-pin 2.54 mm female header | C8: 2 | D8: 0.5 | E8: =C8*D8 | F8: V1 | G8: Amazon | H8: Search | I8: Lets the ESP32 plug in and out
A9: Bulk capacitor (C1) | B9: 470 µF 63 V electrolytic, radial 10 mm, 5 mm pitch | C9: 1 | D9: 0.6 | E9: =C9*D9 | F9: V1 | G9: DigiKey | H9: Search
A10: TVS diode (D1) | B10: SMBJ48CA bidirectional, SMB | C10: 1 | D10: 0.5 | E10: =C10*D10 | F10: V1 | G10: DigiKey | H10: Search | I10: Across the 24 VAC input
A11: Rectifier diode (D2) | B11: 1N4007, DO-41 | C11: 1 | D11: 0.1 | E11: =C11*D11 | F11: V1 | G11: DigiKey | H11: Search | I11: Half-wave: keeps C as DC ground
A12: Fuse clips (F1) | B12: 5x20 mm PCB fuse clip (Littelfuse 111 style) | C12: 2 | D12: 0.3 | E12: =C12*D12 | F12: V1 | G12: DigiKey | H12: Search | I12: Two clips per fuse
A13: Fuse (F1) | B13: 0.5 A fast-blow, 5x20 mm | C13: 1 | D13: 0.5 | E13: =C13*D13 | F13: V1 | G13: DigiKey | H13: Search
A14: Buck module (U2) | B14: LM2596HV module (60 V input), set to 5.00 V before fitting | C14: 1 | D14: 4 | E14: =C14*D14 | F14: V1 | G14: Amazon | H14: Search | I14: Must be the HV version: 24 VAC rectifies to ~40 V peak
A15: Bypass capacitors (C2, C6) | B15: 0.1 µF ceramic disc, 2.5 mm pitch | C15: 2 | D15: 0.1 | E15: =C15*D15 | F15: V1 | G15: DigiKey | H15: Search | I15: C6 is the radio decoupling cap
A16: SETUP button (SW1) | B16: 6 mm through-hole tactile switch | C16: 1 | D16: 0.2 | E16: =C16*D16 | F16: V1 | G16: DigiKey | H16: Search | I16: GPIO14; reserved for Bluetooth setup, no firmware yet
A17: Mode inputs and temperature
A18: Mode-input optos (U3-U6) | B18: H11AA1, DIP-6 | C18: 4 | D18: 0.8 | E18: =C18*D18 | F18: V1 | G18: DigiKey | H18: Search | I18: Y, W, G, O/B
A19: DIP-6 sockets for U3-U6 | B19: 6-pin DIP socket, 7.62 mm | C19: 4 | D19: 0.2 | E19: =C19*D19 | F19: V1 | G19: DigiKey | H19: Search
A20: Opto series resistors (R2, R4, R6, R8) | B20: 4.7k ½ W | C20: 4 | D20: 0.1 | E20: =C20*D20 | F20: V1 | G20: DigiKey | H20: Search
A21: Opto pull-ups (R3, R5, R7, R9) | B21: 10k ¼ W | C21: 4 | D21: 0.05 | E21: =C21*D21 | F21: V1 | G21: DigiKey | H21: Search
A22: DS18B20 pull-up (R1) | B22: 4.7k ¼ W | C22: 1 | D22: 0.05 | E22: =C22*D22 | F22: V1 | G22: DigiKey | H22: Search
A23: Sensor hub (humidity + static pressure)
A24: I²C multiplexer (U7) | B24: TCA9548A, TSSOP-24 (0x70) | C24: 1 | D24: 1.6 | E24: =C24*D24 | F24: V1 | G24: DigiKey | H24: Search | I24: Soldered on the board; replaces the plug-in mux breakout
A25: Mux decoupling cap (C3) | B25: 0.1 µF, 0805 | C25: 1 | D25: 0.05 | E25: =C25*D25 | F25: V1 | G25: DigiKey | H25: Search
A26: Pull-ups and address (R10-R20) | B26: 10k, 0805 | C26: 11 | D26: 0.05 | E26: =C26*D26 | F26: V1 | G26: DigiKey | H26: Search
A27: Connectors (board side + mating plug)
A28: Pluggable terminal (J1) | B28: Phoenix MC 1,5/2-G-5.08 header + MC 1,5/2-ST-5.08 plug | C28: 1 | D28: 2 | E28: =C28*D28 | F28: V1 | G28: DigiKey | H28: Search | I28: 24 VAC in (R, C)
A29: Pluggable terminal (J2) | B29: Phoenix MC 1,5/4-G-5.08 header + MC 1,5/4-ST-5.08 plug | C29: 1 | D29: 3 | E29: =C29*D29 | F29: V1 | G29: DigiKey | H29: Search | I29: Y, W, G, O/B call inputs
A30: Pluggable terminal (J5) | B30: Phoenix MC 1,5/4-G-5.08 header + MC 1,5/4-ST-5.08 plug | C30: 1 | D30: 3 | E30: =C30*D30 | F30: V1 | G30: DigiKey | H30: Search | I30: I²C expansion (spare)
A31: JST-XH 3-pin jack (J3, J4) | B31: B3B-XH-A vertical + XHP-3 housing + SXH crimps | C31: 2 | D31: 0.3 | E31: =C31*D31 | F31: V1 | G31: DigiKey | H31: Search | I31: DS18B20 supply and return air
A32: JST-XH 4-pin jack (J6-J10) | B32: B4B-XH-A vertical + XHP-4 housing + SXH crimps | C32: 5 | D32: 0.35 | E32: =C32*D32 | F32: V1 | G32: DigiKey | H32: Search | I32: SHT45 return/supply (ch 0, 1), SDP810 return/supply/filter (ch 2-4)
A33: LoRa radio and antenna
A34: LoRa module (U8) | B34: Seeed Wio-SX1262 (FCC Z4T-WIO-SX1262), solders flat on the board | C34: 1 | D34: 9 | E34: =C34*D34 | F34: LoRa | G34: Seeed | H34: Search | I34: Same module as the LoRa Radio sheet; counted there for the node totals
A35: Radio regulator (U9) | B35: AMS1117-3.3, SOT-223 | C35: 1 | D35: 0.3 | E35: =C35*D35 | F35: LoRa | G35: DigiKey | H35: Search | I35: Own 3.3 V rail for the radio
A36: Regulator input cap (C4) | B36: 10 µF 16 V electrolytic, radial 5 mm | C36: 1 | D36: 0.15 | E36: =C36*D36 | F36: LoRa | G36: DigiKey | H36: Search
A37: Regulator output cap (C5) | B37: 22 µF 10 V electrolytic, radial 5 mm | C37: 1 | D37: 0.15 | E37: =C37*D37 | F37: LoRa | G37: DigiKey | H37: Search
A38: RF pigtail | B38: u.FL (IPEX) to SMA bulkhead, 15 cm | C38: 1 | D38: 4 | E38: =C38*D38 | F38: LoRa | G38: Amazon | H38: Search | I38: Also on the LoRa Radio sheet
A39: 915 MHz antenna | B39: 915 MHz 3 dBi, SMA, outdoor-rated | C39: 1 | D39: 12 | E39: =C39*D39 | F39: LoRa | G39: Amazon | H39: Search | I39: Also on the LoRa Radio sheet. Must be 915, not 868
D41: Total | E41: =SUM(E5:E39)
...
